<?xml version="1.0"?>
<robot name="unita_car">
  <link name="base_link"/>
  <link name="chassis">
    <visual>
      <origin xyz="0.01 0 -0.0308243" rpy="0 0 1.57"/>
      <geometry>
        <mesh filename="package://description_package/meshes/chassis.stl" scale="0.0115 0.01 0.01"/>
      </geometry>
      <material name="body_gray">
        <color rgba="0.65 0.65 0.65 1.0"/>
      </material>
    </visual>
  </link>
  <joint name="chassis_joint" type="fixed">
    <parent link="base_link"/>
    <child link="chassis"/>
    <origin xyz="0 0 0.075" rpy="0 0 0"/>
  </joint>


    <!-- LiDAR -->
  <link name="lidar_link">
    <visual>
      <geometry>
        <!--box size="0.0556 0.0556 0.0413"/-->
        <mesh filename="package://description_package/meshes/lidar.stl" scale="1 1 1"/>
      </geometry>
      <material name="black">
        <color rgba="0.1 0.1 0.1 1.0"/>
      </material>
    </visual>
  </link>
  <joint name="lidar_joint" type="fixed">
    <parent link="chassis"/>
    <child link="lidar_link"/>
    <origin xyz="0.4725 0 0.081" rpy="0 0 0"/>
  </joint>

  <!-- Ultrasonic left (1) -->
  <link name="ultrasonic1_1_link">
    <visual>
      <geometry>
        <mesh filename="package://description_package/meshes/ultrasonic.stl" scale="1 1 1"/>
      </geometry>
      <material name="blue">
        <color rgba="0.0 0.0 1.0 1.0"/>
      </material>
    </visual>
  </link>
  <joint name="ultrasonic1_1_joint" type="fixed"> 
    <parent link="chassis"/><child link="ultrasonic1_1_link"/>
    <origin xyz="-0.5 0.099 0.104" rpy="0 0 3.0527"/>
  </joint>

  <link name="ultrasonic1_2_link">
    <visual>
      <geometry>
        <mesh filename="package://description_package/meshes/ultrasonic.stl" scale="1 1 1"/>
      </geometry>
      <material name="blue">
        <color rgba="0.0 0.0 1.0 1.0"/>
      </material>
    </visual>
  </link>
  <joint name="ultrasonic1_2_joint" type="fixed">
    <parent link="chassis"/><child link="ultrasonic1_2_link"/>
    <origin xyz="-0.478 0.172 0.104" rpy="0 0 2.7386"/>
  </joint>

  <link name="ultrasonic1_3_link">
    <visual>
      <geometry>
        <mesh filename="package://description_package/meshes/ultrasonic.stl" scale="1 1 1"/>
      </geometry>
      <material name="blue">
        <color rgba="0.0 0.0 1.0 1.0"/>
      </material>
    </visual>
  </link>
  <joint name="ultrasonic1_3_joint" type="fixed">
    <parent link="chassis"/><child link="ultrasonic1_3_link"/>
    <origin xyz="-0.42 0.246 0.104" rpy="0 0 2.2324"/>
  </joint>

  <!-- Ultrasonic right (2) -->
  <link name="ultrasonic2_1_link">
    <visual>
      <geometry>
        <mesh filename="package://description_package/meshes/ultrasonic.stl" scale="1 1 1"/>
      </geometry>
      <material name="blue">
        <color rgba="0.0 0.0 1.0 1.0"/>
      </material>
    </visual>
  </link>
  <joint name="ultrasonic2_1_joint" type="fixed">
    <parent link="chassis"/><child link="ultrasonic2_1_link"/>
    <origin xyz="-0.5 -0.099 0.104" rpy="0 0 -3.0527"/>
  </joint>

  <link name="ultrasonic2_2_link">
    <visual>
      <geometry>
        <mesh filename="package://description_package/meshes/ultrasonic.stl" scale="1 1 1"/>
      </geometry>
      <material name="blue">
        <color rgba="0.0 0.0 1.0 1.0"/>
      </material>
    </visual>
  </link>
  <joint name="ultrasonic2_2_joint" type="fixed">
    <parent link="chassis"/><child link="ultrasonic2_2_link"/>
    <origin xyz="-0.478 -0.172 0.104" rpy="0 0 -2.7386"/>
  </joint>

  <link name="ultrasonic2_3_link">
    <visual>
      <geometry>
        <mesh filename="package://description_package/meshes/ultrasonic.stl" scale="1 1 1"/>
      </geometry>
      <material name="blue">
        <color rgba="0.0 0.0 1.0 1.0"/>
      </material>
    </visual>
  </link>
  <joint name="ultrasonic2_3_joint" type="fixed">
    <parent link="chassis"/><child link="ultrasonic2_3_link"/>
    <origin xyz="-0.42 -0.246 0.104" rpy="0 0 -2.2324"/>
  </joint>


  <!-- Cameras -->
  <link name="camera1_link">
    <visual>
      <origin xyz="-0.05 -0.0113 0.0018" rpy="-1.57 0 0"/>
      <geometry>
        <mesh filename="package://description_package/meshes/camera.stl" scale="0.001 0.001 0.001"/>
      </geometry>
      <material name="red">
        <color rgba="1.0 0.0 0 1.0"/>
      </material>
    </visual>
  </link>
  <joint name="camera1_joint" type="fixed">
    <parent link="chassis"/>
    <child link="camera1_link"/>
    <origin xyz="-0.42 0 0.525" rpy="1.57 3.14 1.57"/>
  </joint>

  <link name="camera2_link">
    <visual>
      <origin xyz="-0.05 -0.0113 0.0018" rpy="-1.57 0 0"/>
      <geometry>
        <mesh filename="package://description_package/meshes/camera.stl" scale="0.001 0.001 0.001"/>
      </geometry>
      <material name="red">
        <color rgba="1.0 0.0 0 1.0"/>
      </material>
    </visual>
  </link>
  <joint name="camera2_joint" type="fixed">
    <parent link="chassis"/>
    <child link="camera2_link"/>
    <origin xyz="-0.42 -0.06 0.525" rpy="1.57 3.14 1.57"/>
  </joint>

  <!-- Wheels-->
  <link name="wheel_rear_left_link">
    <visual>
      <origin xyz="0 0 0" rpy="0 0 1.57"/>
      <geometry>
        <mesh filename="package://description_package/meshes/wheel.stl" scale="0.00215 0.0032 0.0032"/>
      </geometry>
      <material name="black">
        <color rgba="0.1 0.1 0.1 1.0"/>
      </material>
    </visual>
  </link>
  <joint name="wheel_rear_left_joint" type="continuous">
    <parent link="chassis"/>
    <child link="wheel_rear_left_link"/>
    <origin xyz="-0.2975 0.221 0.023" rpy="0 0 0"/>
    <axis xyz="0 1 0"/>
  </joint>
  <link name="wheel_rear_right_link">
    <visual>
      <origin xyz="0 0 0" rpy="0 0 1.57"/>
      <geometry>
        <mesh filename="package://description_package/meshes/wheel.stl" scale="0.00215 0.0032 0.0032"/>
      </geometry>
      <material name="black">
        <color rgba="0.1 0.1 0.1 1.0"/>
      </material>
    </visual>
  </link>
  <joint name="wheel_rear_right_joint" type="continuous">
    <parent link="chassis"/>
    <child link="wheel_rear_right_link"/>
    <origin xyz="-0.2975 -0.221 0.023" rpy="0 0 0"/>
    <axis xyz="0 1 0"/>
  </joint>
  <!-- front wheel-->
  <link name="front_left_wheel_axle"></link>
  <joint name="front_left_wheel_axle_joint" type="continuous">
    <parent link="chassis"/>
    <child link="front_left_wheel_axle"/>
    <origin xyz="0.2475 0.221 0.023" rpy="0 0 0"/>
    <axis xyz="0 0 1"/>
  </joint>
  <link name="wheel_front_left_link">
    <visual>
      <origin xyz="0 0 0" rpy="0 0 1.57"/>
      <geometry>
        <mesh filename="package://description_package/meshes/wheel.stl" scale="0.00215 0.0032 0.0032"/>
      </geometry>
      <material name="black">
        <color rgba="0.1 0.1 0.1 1.0"/>
      </material>
    </visual>
  </link>
  <joint name="wheel_front_left_joint" type="continuous">
    <parent link="front_left_wheel_axle"/>
    <child link="wheel_front_left_link"/>
    <origin xyz="0 0 0"/>
    <axis xyz="0 1 0"/>
  </joint>
  <link name="front_right_wheel_axle"></link>
  <joint name="front_right_wheel_axle_joint" type="continuous">
    <parent link="chassis"/>
    <child link="front_right_wheel_axle"/>
    <origin xyz="0.2475 -0.221 0.023" rpy="0 0 0"/>
    <axis xyz="0 0 1"/>
  </joint>
  <link name="wheel_front_right_link">
    <visual>
      <origin xyz="0 0 0" rpy="0 0 1.57"/>
      <geometry>
        <mesh filename="package://description_package/meshes/wheel.stl" scale="0.00215 0.0032 0.0032"/>
      </geometry>
      <material name="black">
        <color rgba="0.1 0.1 0.1 1.0"/>
      </material>
    </visual>
  </link>
  <joint name="wheel_front_right_joint" type="continuous">
    <parent link="front_right_wheel_axle"/>
    <child link="wheel_front_right_link"/>
    <origin xyz="0 0 0"/>
    <axis xyz="0 1 0"/>
  </joint>
  
  
</robot>  